<?xml version="1.0" encoding="UTF-8"?>
<!-- Generated by org.testng.reporters.JUnitReportReporter -->
<testsuite hostname="LAPTOP-VCQHI407" failures="0" tests="15" name="com.nkxgen.spring.jdbc.Test.LoanControllerTest" time="1.847" errors="2" timestamp="2023-07-09T12:11:14 IST" skipped="0">
  <testcase classname="com.nkxgen.spring.jdbc.Test.LoanControllerTest" name="testGetLoanApplicationById_Success" time="0.005"/>
  <testcase classname="com.nkxgen.spring.jdbc.Test.LoanControllerTest" name="testGetLoanApplicationById_ApplicationNotFound" time="0.005"/>
  <testcase classname="com.nkxgen.spring.jdbc.Test.LoanControllerTest" name="testGetLoanApplication_PermissionDenied" time="0.003"/>
  <testcase classname="com.nkxgen.spring.jdbc.Test.LoanControllerTest" name="testDeleteLoanApplication_Success" time="0.005"/>
  <testcase classname="com.nkxgen.spring.jdbc.Test.LoanControllerTest" name="testDeleteLoanApplication_Exception" time="0.017">
    <error message="
Checked exception is invalid for this method!
Invalid: java.lang.Exception" type="org.mockito.exceptions.base.MockitoException">
      <![CDATA[org.mockito.exceptions.base.MockitoException: 
Checked exception is invalid for this method!
Invalid: java.lang.Exception
at com.nkxgen.spring.jdbc.Test.LoanControllerTest.testDeleteLoanApplication_Exception(LoanControllerTest.java:273)
at java.base/jdk.internal.reflect.NativeMethodAccessorImpl.invoke0(Native Method)
at java.base/jdk.internal.reflect.NativeMethodAccessorImpl.invoke(NativeMethodAccessorImpl.java:77)
at java.base/jdk.internal.reflect.DelegatingMethodAccessorImpl.invoke(DelegatingMethodAccessorImpl.java:43)
at java.base/java.lang.reflect.Method.invoke(Method.java:568)
at org.testng.internal.invokers.MethodInvocationHelper.invokeMethod(MethodInvocationHelper.java:139)
at org.testng.internal.invokers.TestInvoker.invokeMethod(TestInvoker.java:664)
at org.testng.internal.invokers.TestInvoker.invokeTestMethod(TestInvoker.java:227)
at org.testng.internal.invokers.MethodRunner.runInSequence(MethodRunner.java:50)
at org.testng.internal.invokers.TestInvoker$MethodInvocationAgent.invoke(TestInvoker.java:957)
at org.testng.internal.invokers.TestInvoker.invokeTestMethods(TestInvoker.java:200)
at org.testng.internal.invokers.TestMethodWorker.invokeTestMethods(TestMethodWorker.java:148)
at org.testng.internal.invokers.TestMethodWorker.run(TestMethodWorker.java:128)
at java.base/java.util.ArrayList.forEach(ArrayList.java:1511)
at org.testng.TestRunner.privateRun(TestRunner.java:848)
at org.testng.TestRunner.run(TestRunner.java:621)
at org.testng.SuiteRunner.runTest(SuiteRunner.java:443)
at org.testng.SuiteRunner.runSequentially(SuiteRunner.java:437)
at org.testng.SuiteRunner.privateRun(SuiteRunner.java:397)
at org.testng.SuiteRunner.run(SuiteRunner.java:336)
at org.testng.SuiteRunnerWorker.runSuite(SuiteRunnerWorker.java:52)
at org.testng.SuiteRunnerWorker.run(SuiteRunnerWorker.java:95)
at org.testng.TestNG.runSuitesSequentially(TestNG.java:1280)
at org.testng.TestNG.runSuitesLocally(TestNG.java:1200)
at org.testng.TestNG.runSuites(TestNG.java:1114)
at org.testng.TestNG.run(TestNG.java:1082)
at com.nkxgen.spring.jdbc.Test.LoanControllerTestRunner.main(LoanControllerTestRunner.java:20)
]]>
    </error>
  </testcase> <!-- testDeleteLoanApplication_Exception -->
  <testcase classname="com.nkxgen.spring.jdbc.Test.LoanControllerTest" name="testGetAccountById_Success" time="0.006"/>
  <testcase classname="com.nkxgen.spring.jdbc.Test.LoanControllerTest" name="testApproveLoanApplication_Success" time="0.046"/>
  <testcase classname="com.nkxgen.spring.jdbc.Test.LoanControllerTest" name="testLoanNewApplicationForm" time="1.722"/>
  <testcase classname="com.nkxgen.spring.jdbc.Test.LoanControllerTest" name="testUpdateLoanApplication_Success" time="0.003"/>
  <testcase classname="com.nkxgen.spring.jdbc.Test.LoanControllerTest" name="testGetLoanAccounts_PermissionGranted" time="0.006"/>
  <testcase classname="com.nkxgen.spring.jdbc.Test.LoanControllerTest" name="testRedirectForm" time="0.004"/>
  <testcase classname="com.nkxgen.spring.jdbc.Test.LoanControllerTest" name="testGetAccountById_AccountNotFound" time="0.005"/>
  <testcase classname="com.nkxgen.spring.jdbc.Test.LoanControllerTest" name="testUpdateLoanApplication_Exception" time="0.004">
    <error message="
Checked exception is invalid for this method!
Invalid: java.lang.Exception" type="org.mockito.exceptions.base.MockitoException">
      <![CDATA[org.mockito.exceptions.base.MockitoException: 
Checked exception is invalid for this method!
Invalid: java.lang.Exception
at com.nkxgen.spring.jdbc.Test.LoanControllerTest.testUpdateLoanApplication_Exception(LoanControllerTest.java:170)
at java.base/jdk.internal.reflect.NativeMethodAccessorImpl.invoke0(Native Method)
at java.base/jdk.internal.reflect.NativeMethodAccessorImpl.invoke(NativeMethodAccessorImpl.java:77)
at java.base/jdk.internal.reflect.DelegatingMethodAccessorImpl.invoke(DelegatingMethodAccessorImpl.java:43)
at java.base/java.lang.reflect.Method.invoke(Method.java:568)
at org.testng.internal.invokers.MethodInvocationHelper.invokeMethod(MethodInvocationHelper.java:139)
at org.testng.internal.invokers.TestInvoker.invokeMethod(TestInvoker.java:664)
at org.testng.internal.invokers.TestInvoker.invokeTestMethod(TestInvoker.java:227)
at org.testng.internal.invokers.MethodRunner.runInSequence(MethodRunner.java:50)
at org.testng.internal.invokers.TestInvoker$MethodInvocationAgent.invoke(TestInvoker.java:957)
at org.testng.internal.invokers.TestInvoker.invokeTestMethods(TestInvoker.java:200)
at org.testng.internal.invokers.TestMethodWorker.invokeTestMethods(TestMethodWorker.java:148)
at org.testng.internal.invokers.TestMethodWorker.run(TestMethodWorker.java:128)
at java.base/java.util.ArrayList.forEach(ArrayList.java:1511)
at org.testng.TestRunner.privateRun(TestRunner.java:848)
at org.testng.TestRunner.run(TestRunner.java:621)
at org.testng.SuiteRunner.runTest(SuiteRunner.java:443)
at org.testng.SuiteRunner.runSequentially(SuiteRunner.java:437)
at org.testng.SuiteRunner.privateRun(SuiteRunner.java:397)
at org.testng.SuiteRunner.run(SuiteRunner.java:336)
at org.testng.SuiteRunnerWorker.runSuite(SuiteRunnerWorker.java:52)
at org.testng.SuiteRunnerWorker.run(SuiteRunnerWorker.java:95)
at org.testng.TestNG.runSuitesSequentially(TestNG.java:1280)
at org.testng.TestNG.runSuitesLocally(TestNG.java:1200)
at org.testng.TestNG.runSuites(TestNG.java:1114)
at org.testng.TestNG.run(TestNG.java:1082)
at com.nkxgen.spring.jdbc.Test.LoanControllerTestRunner.main(LoanControllerTestRunner.java:20)
]]>
    </error>
  </testcase> <!-- testUpdateLoanApplication_Exception -->
  <testcase classname="com.nkxgen.spring.jdbc.Test.LoanControllerTest" name="testGetLoanApplication_PermissionGranted" time="0.010"/>
  <testcase classname="com.nkxgen.spring.jdbc.Test.LoanControllerTest" name="testNewLoanApplication_Success" time="0.006"/>
</testsuite> <!-- com.nkxgen.spring.jdbc.Test.LoanControllerTest -->
